Mon Dec 02 20:47:30 COT 2019 : Apache Derby Network Server - 10.11.1.2 - (1629631) started and ready to accept connections on port 1527
----------------------------------------------------------------
Mon Dec 02 20:47:30 COT 2019:
Booting Derby version The Apache Software Foundation - Apache Derby - 10.11.1.2 - (1629631): instance a816c00e-016e-c970-e77f-000057633615 
on database directory C:\Users\NikcQ\Documents\NetBeansProjects\CinemaTickets\cinemAppDB_JPA with class loader sun.misc.Launcher$AppClassLoader@1d44bcfa 
Loaded from file:/C:/Program%20Files/Java/jdk1.8.0_111/db/lib/derby.jar
java.vendor=Oracle Corporation
java.runtime.version=1.8.0_221-b11
user.dir=C:\Program Files\Java\jdk1.8.0_111\db
os.name=Windows 10
os.arch=amd64
os.version=10.0
derby.system.home=C:\Users\NikcQ\Documents\NetBeansProjects\CinemaTickets
Database Class Loader started - derby.database.classpath=''
Mon Dec 02 20:47:30 COT 2019 Thread[DRDAConnThread_2,5,main] (XID = 4155), (SESSIONID = 0), (DATABASE = cinemAppDB_JPA), (DRDAID = {1}), Cleanup action starting
java.sql.SQLNonTransientConnectionException: Se ha producido un fallo de autenticación de conexión. Motivo: Autenticación no válida..
	at org.apache.derby.impl.jdbc.SQLExceptionFactory.getSQLException(Unknown Source)
	at org.apache.derby.impl.jdbc.SQLExceptionFactory.getSQLException(Unknown Source)
	at org.apache.derby.impl.jdbc.Util.generateCsSQLException(Unknown Source)
	at org.apache.derby.impl.jdbc.Util.generateCsSQLException(Unknown Source)
	at org.apache.derby.impl.jdbc.EmbedConnection.newSQLException(Unknown Source)
	at org.apache.derby.impl.jdbc.EmbedConnection.checkUserCredentials(Unknown Source)
	at org.apache.derby.impl.jdbc.EmbedConnection.<init>(Unknown Source)
	at org.apache.derby.jdbc.InternalDriver.getNewEmbedConnection(Unknown Source)
	at org.apache.derby.jdbc.InternalDriver.connect(Unknown Source)
	at org.apache.derby.jdbc.InternalDriver.connect(Unknown Source)
	at org.apache.derby.jdbc.EmbeddedDriver.connect(Unknown Source)
	at org.apache.derby.impl.drda.Database.makeConnection(Unknown Source)
	at org.apache.derby.impl.drda.DRDAConnThread.getConnFromDatabaseName(Unknown Source)
	at org.apache.derby.impl.drda.DRDAConnThread.verifyUserIdPassword(Unknown Source)
	at org.apache.derby.impl.drda.DRDAConnThread.parseSECCHK(Unknown Source)
	at org.apache.derby.impl.drda.DRDAConnThread.parseDRDAConnection(Unknown Source)
	at org.apache.derby.impl.drda.DRDAConnThread.processCommands(Unknown Source)
	at org.apache.derby.impl.drda.DRDAConnThread.run(Unknown Source)
Caused by: ERROR 08004: Se ha producido un fallo de autenticación de conexión. Motivo: Autenticación no válida..
	at org.apache.derby.iapi.error.StandardException.newException(Unknown Source)
	at org.apache.derby.impl.jdbc.SQLExceptionFactory.wrapArgsForTransportAcrossDRDA(Unknown Source)
	... 18 more
============= begin nested exception, level (1) ===========
ERROR 08004: Se ha producido un fallo de autenticación de conexión. Motivo: Autenticación no válida..
	at org.apache.derby.iapi.error.StandardException.newException(Unknown Source)
	at org.apache.derby.impl.jdbc.SQLExceptionFactory.wrapArgsForTransportAcrossDRDA(Unknown Source)
	at org.apache.derby.impl.jdbc.SQLExceptionFactory.getSQLException(Unknown Source)
	at org.apache.derby.impl.jdbc.SQLExceptionFactory.getSQLException(Unknown Source)
	at org.apache.derby.impl.jdbc.Util.generateCsSQLException(Unknown Source)
	at org.apache.derby.impl.jdbc.Util.generateCsSQLException(Unknown Source)
	at org.apache.derby.impl.jdbc.EmbedConnection.newSQLException(Unknown Source)
	at org.apache.derby.impl.jdbc.EmbedConnection.checkUserCredentials(Unknown Source)
	at org.apache.derby.impl.jdbc.EmbedConnection.<init>(Unknown Source)
	at org.apache.derby.jdbc.InternalDriver.getNewEmbedConnection(Unknown Source)
	at org.apache.derby.jdbc.InternalDriver.connect(Unknown Source)
	at org.apache.derby.jdbc.InternalDriver.connect(Unknown Source)
	at org.apache.derby.jdbc.EmbeddedDriver.connect(Unknown Source)
	at org.apache.derby.impl.drda.Database.makeConnection(Unknown Source)
	at org.apache.derby.impl.drda.DRDAConnThread.getConnFromDatabaseName(Unknown Source)
	at org.apache.derby.impl.drda.DRDAConnThread.verifyUserIdPassword(Unknown Source)
	at org.apache.derby.impl.drda.DRDAConnThread.parseSECCHK(Unknown Source)
	at org.apache.derby.impl.drda.DRDAConnThread.parseDRDAConnection(Unknown Source)
	at org.apache.derby.impl.drda.DRDAConnThread.processCommands(Unknown Source)
	at org.apache.derby.impl.drda.DRDAConnThread.run(Unknown Source)
============= end nested exception, level (1) ===========
Cleanup action completed
Mon Dec 02 20:47:30 COT 2019 Thread[DRDAConnThread_2,5,main] (DATABASE = cinemAppDB_JPA), (DRDAID = {1}), Se ha producido un fallo de autenticación de conexión. Motivo: Autenticación no válida..
